[2024-04-02 12:58:51,019] {taskinstance.py:1159} INFO - Dependencies all met for <TaskInstance: get_stocks_dag.AAPL scheduled__2024-01-11T00:00:00+00:00 [queued]>
[2024-04-02 12:58:51,026] {taskinstance.py:1159} INFO - Dependencies all met for <TaskInstance: get_stocks_dag.AAPL scheduled__2024-01-11T00:00:00+00:00 [queued]>
[2024-04-02 12:58:51,027] {taskinstance.py:1356} INFO - 
--------------------------------------------------------------------------------
[2024-04-02 12:58:51,027] {taskinstance.py:1357} INFO - Starting attempt 1 of 1
[2024-04-02 12:58:51,027] {taskinstance.py:1358} INFO - 
--------------------------------------------------------------------------------
[2024-04-02 12:58:51,063] {taskinstance.py:1377} INFO - Executing <Task(_PythonDecoratedOperator): AAPL> on 2024-01-11 00:00:00+00:00
[2024-04-02 12:58:51,069] {standard_task_runner.py:52} INFO - Started process 8485 to run task
[2024-04-02 12:58:51,075] {standard_task_runner.py:79} INFO - Running: ['airflow', 'tasks', 'run', 'get_stocks_dag', 'AAPL', 'scheduled__2024-01-11T00:00:00+00:00', '--job-id', '35', '--raw', '--subdir', 'DAGS_FOLDER/get_stocks.py', '--cfg-path', '/tmp/tmpj1rdrb7v', '--error-file', '/tmp/tmp6tmepbze']
[2024-04-02 12:58:51,077] {standard_task_runner.py:80} INFO - Job 35: Subtask AAPL
[2024-04-02 12:58:51,148] {task_command.py:370} INFO - Running <TaskInstance: get_stocks_dag.AAPL scheduled__2024-01-11T00:00:00+00:00 [running]> on host alexmend-virtual-machine
[2024-04-02 12:58:51,218] {taskinstance.py:1569} INFO - Exporting the following env vars:
AIRFLOW_CTX_DAG_OWNER=airflow
AIRFLOW_CTX_DAG_ID=get_stocks_dag
AIRFLOW_CTX_TASK_ID=AAPL
AIRFLOW_CTX_EXECUTION_DATE=2024-01-11T00:00:00+00:00
AIRFLOW_CTX_TRY_NUMBER=1
AIRFLOW_CTX_DAG_RUN_ID=scheduled__2024-01-11T00:00:00+00:00
[2024-04-02 12:58:51,916] {python.py:173} INFO - Done. Returned value was: None
[2024-04-02 12:58:51,930] {taskinstance.py:1395} INFO - Marking task as SUCCESS. dag_id=get_stocks_dag, task_id=AAPL, execution_date=20240111T000000, start_date=20240402T155851, end_date=20240402T155851
[2024-04-02 12:58:51,996] {local_task_job.py:156} INFO - Task exited with return code 0
[2024-04-02 12:58:52,037] {local_task_job.py:273} INFO - 0 downstream tasks scheduled from follow-on schedule check
[2024-04-02 13:48:06,350] {taskinstance.py:1159} INFO - Dependencies all met for <TaskInstance: get_stocks_dag.AAPL scheduled__2024-01-11T00:00:00+00:00 [queued]>
[2024-04-02 13:48:08,591] {taskinstance.py:1159} INFO - Dependencies all met for <TaskInstance: get_stocks_dag.AAPL scheduled__2024-01-11T00:00:00+00:00 [queued]>
[2024-04-02 13:48:08,592] {taskinstance.py:1356} INFO - 
--------------------------------------------------------------------------------
[2024-04-02 13:48:08,593] {taskinstance.py:1357} INFO - Starting attempt 1 of 1
[2024-04-02 13:48:08,600] {taskinstance.py:1358} INFO - 
--------------------------------------------------------------------------------
[2024-04-02 13:48:21,957] {taskinstance.py:1377} INFO - Executing <Task(_PythonDecoratedOperator): AAPL> on 2024-01-11 00:00:00+00:00
[2024-04-02 13:48:27,383] {standard_task_runner.py:52} INFO - Started process 27119 to run task
[2024-04-02 13:48:46,325] {standard_task_runner.py:79} INFO - Running: ['airflow', 'tasks', 'run', 'get_stocks_dag', 'AAPL', 'scheduled__2024-01-11T00:00:00+00:00', '--job-id', '17', '--raw', '--subdir', 'DAGS_FOLDER/get_stocks.py', '--cfg-path', '/tmp/tmpz5p2ltnb', '--error-file', '/tmp/tmped4huzsz']
[2024-04-02 13:48:46,336] {standard_task_runner.py:80} INFO - Job 17: Subtask AAPL
[2024-04-02 13:50:05,769] {base_job.py:229} ERROR - LocalTaskJob heartbeat got an exception
Traceback (most recent call last):
  File "/home/alexmend/Documents/airflowalex/venv/lib/python3.9/site-packages/sqlalchemy/engine/base.py", line 3141, in _wrap_pool_connect
    return fn()
  File "/home/alexmend/Documents/airflowalex/venv/lib/python3.9/site-packages/sqlalchemy/pool/base.py", line 301, in connect
    return _ConnectionFairy._checkout(self)
  File "/home/alexmend/Documents/airflowalex/venv/lib/python3.9/site-packages/sqlalchemy/pool/base.py", line 755, in _checkout
    fairy = _ConnectionRecord.checkout(pool)
  File "/home/alexmend/Documents/airflowalex/venv/lib/python3.9/site-packages/sqlalchemy/pool/base.py", line 419, in checkout
    rec = pool._do_get()
  File "/home/alexmend/Documents/airflowalex/venv/lib/python3.9/site-packages/sqlalchemy/pool/impl.py", line 259, in _do_get
    return self._create_connection()
  File "/home/alexmend/Documents/airflowalex/venv/lib/python3.9/site-packages/sqlalchemy/pool/base.py", line 247, in _create_connection
    return _ConnectionRecord(self)
  File "/home/alexmend/Documents/airflowalex/venv/lib/python3.9/site-packages/sqlalchemy/pool/base.py", line 362, in __init__
    self.__connect(first_connect_check=True)
  File "/home/alexmend/Documents/airflowalex/venv/lib/python3.9/site-packages/sqlalchemy/pool/base.py", line 605, in __connect
    pool.logger.debug("Error on connect(): %s", e)
  File "/home/alexmend/Documents/airflowalex/venv/lib/python3.9/site-packages/sqlalchemy/util/langhelpers.py", line 70, in __exit__
    compat.raise_(
  File "/home/alexmend/Documents/airflowalex/venv/lib/python3.9/site-packages/sqlalchemy/util/compat.py", line 211, in raise_
    raise exception
  File "/home/alexmend/Documents/airflowalex/venv/lib/python3.9/site-packages/sqlalchemy/pool/base.py", line 599, in __connect
    connection = pool._invoke_creator(self)
  File "/home/alexmend/Documents/airflowalex/venv/lib/python3.9/site-packages/sqlalchemy/engine/create.py", line 578, in connect
    return dialect.connect(*cargs, **cparams)
  File "/home/alexmend/Documents/airflowalex/venv/lib/python3.9/site-packages/sqlalchemy/engine/default.py", line 583, in connect
    return self.dbapi.connect(*cargs, **cparams)
  File "/home/alexmend/Documents/airflowalex/venv/lib/python3.9/site-packages/psycopg2/__init__.py", line 122, in connect
    conn = _connect(dsn, connection_factory=connection_factory, **kwasync)
psycopg2.OperationalError: connection to server at "localhost" (127.0.0.1), port 5432 failed: SSL SYSCALL error: EOF detected
could not send startup packet: Connection reset by peer


The above exception was the direct cause of the following exception:

Traceback (most recent call last):
  File "/home/alexmend/Documents/airflowalex/venv/lib/python3.9/site-packages/airflow/jobs/base_job.py", line 219, in heartbeat
    session.merge(self)
  File "/home/alexmend/Documents/airflowalex/venv/lib/python3.9/site-packages/sqlalchemy/orm/session.py", line 2872, in merge
    return self._merge(
  File "/home/alexmend/Documents/airflowalex/venv/lib/python3.9/site-packages/sqlalchemy/orm/session.py", line 2950, in _merge
    merged = self.get(mapper.class_, key[1], identity_token=key[2])
  File "/home/alexmend/Documents/airflowalex/venv/lib/python3.9/site-packages/sqlalchemy/orm/session.py", line 2695, in get
    return self._get_impl(
  File "/home/alexmend/Documents/airflowalex/venv/lib/python3.9/site-packages/sqlalchemy/orm/session.py", line 2796, in _get_impl
    return db_load_fn(
  File "/home/alexmend/Documents/airflowalex/venv/lib/python3.9/site-packages/sqlalchemy/orm/loading.py", line 531, in load_on_pk_identity
    session.execute(
  File "/home/alexmend/Documents/airflowalex/venv/lib/python3.9/site-packages/sqlalchemy/orm/session.py", line 1669, in execute
    conn = self._connection_for_bind(bind, close_with_result=True)
  File "/home/alexmend/Documents/airflowalex/venv/lib/python3.9/site-packages/sqlalchemy/orm/session.py", line 1519, in _connection_for_bind
    return self._transaction._connection_for_bind(
  File "/home/alexmend/Documents/airflowalex/venv/lib/python3.9/site-packages/sqlalchemy/orm/session.py", line 747, in _connection_for_bind
    conn = bind.connect()
  File "/home/alexmend/Documents/airflowalex/venv/lib/python3.9/site-packages/sqlalchemy/engine/base.py", line 3095, in connect
    return self._connection_cls(self, close_with_result=close_with_result)
  File "/home/alexmend/Documents/airflowalex/venv/lib/python3.9/site-packages/sqlalchemy/engine/base.py", line 91, in __init__
    else engine.raw_connection()
  File "/home/alexmend/Documents/airflowalex/venv/lib/python3.9/site-packages/sqlalchemy/engine/base.py", line 3174, in raw_connection
    return self._wrap_pool_connect(self.pool.connect, _connection)
  File "/home/alexmend/Documents/airflowalex/venv/lib/python3.9/site-packages/sqlalchemy/engine/base.py", line 3144, in _wrap_pool_connect
    Connection._handle_dbapi_exception_noconnection(
  File "/home/alexmend/Documents/airflowalex/venv/lib/python3.9/site-packages/sqlalchemy/engine/base.py", line 2003, in _handle_dbapi_exception_noconnection
    util.raise_(
  File "/home/alexmend/Documents/airflowalex/venv/lib/python3.9/site-packages/sqlalchemy/util/compat.py", line 211, in raise_
    raise exception
  File "/home/alexmend/Documents/airflowalex/venv/lib/python3.9/site-packages/sqlalchemy/engine/base.py", line 3141, in _wrap_pool_connect
    return fn()
  File "/home/alexmend/Documents/airflowalex/venv/lib/python3.9/site-packages/sqlalchemy/pool/base.py", line 301, in connect
    return _ConnectionFairy._checkout(self)
  File "/home/alexmend/Documents/airflowalex/venv/lib/python3.9/site-packages/sqlalchemy/pool/base.py", line 755, in _checkout
    fairy = _ConnectionRecord.checkout(pool)
  File "/home/alexmend/Documents/airflowalex/venv/lib/python3.9/site-packages/sqlalchemy/pool/base.py", line 419, in checkout
    rec = pool._do_get()
  File "/home/alexmend/Documents/airflowalex/venv/lib/python3.9/site-packages/sqlalchemy/pool/impl.py", line 259, in _do_get
    return self._create_connection()
  File "/home/alexmend/Documents/airflowalex/venv/lib/python3.9/site-packages/sqlalchemy/pool/base.py", line 247, in _create_connection
    return _ConnectionRecord(self)
  File "/home/alexmend/Documents/airflowalex/venv/lib/python3.9/site-packages/sqlalchemy/pool/base.py", line 362, in __init__
    self.__connect(first_connect_check=True)
  File "/home/alexmend/Documents/airflowalex/venv/lib/python3.9/site-packages/sqlalchemy/pool/base.py", line 605, in __connect
    pool.logger.debug("Error on connect(): %s", e)
  File "/home/alexmend/Documents/airflowalex/venv/lib/python3.9/site-packages/sqlalchemy/util/langhelpers.py", line 70, in __exit__
    compat.raise_(
  File "/home/alexmend/Documents/airflowalex/venv/lib/python3.9/site-packages/sqlalchemy/util/compat.py", line 211, in raise_
    raise exception
  File "/home/alexmend/Documents/airflowalex/venv/lib/python3.9/site-packages/sqlalchemy/pool/base.py", line 599, in __connect
    connection = pool._invoke_creator(self)
  File "/home/alexmend/Documents/airflowalex/venv/lib/python3.9/site-packages/sqlalchemy/engine/create.py", line 578, in connect
    return dialect.connect(*cargs, **cparams)
  File "/home/alexmend/Documents/airflowalex/venv/lib/python3.9/site-packages/sqlalchemy/engine/default.py", line 583, in connect
    return self.dbapi.connect(*cargs, **cparams)
  File "/home/alexmend/Documents/airflowalex/venv/lib/python3.9/site-packages/psycopg2/__init__.py", line 122, in connect
    conn = _connect(dsn, connection_factory=connection_factory, **kwasync)
sqlalchemy.exc.OperationalError: (psycopg2.OperationalError) connection to server at "localhost" (127.0.0.1), port 5432 failed: SSL SYSCALL error: EOF detected
could not send startup packet: Connection reset by peer

(Background on this error at: http://sqlalche.me/e/14/e3q8)
[2024-04-02 13:53:33,406] {standard_task_runner.py:92} ERROR - Failed to execute job 17 for task AAPL ((psycopg2.OperationalError) connection to server at "localhost" (127.0.0.1), port 5432 failed: Connection refused
	Is the server running on that host and accepting TCP/IP connections?

(Background on this error at: http://sqlalche.me/e/14/e3q8); 27119)
[2024-04-02 17:42:28,592] {taskinstance.py:1159} INFO - Dependencies all met for <TaskInstance: get_stocks_dag.AAPL scheduled__2024-01-11T00:00:00+00:00 [queued]>
[2024-04-02 17:42:28,616] {taskinstance.py:1159} INFO - Dependencies all met for <TaskInstance: get_stocks_dag.AAPL scheduled__2024-01-11T00:00:00+00:00 [queued]>
[2024-04-02 17:42:28,617] {taskinstance.py:1356} INFO - 
--------------------------------------------------------------------------------
[2024-04-02 17:42:28,617] {taskinstance.py:1357} INFO - Starting attempt 1 of 1
[2024-04-02 17:42:28,617] {taskinstance.py:1358} INFO - 
--------------------------------------------------------------------------------
[2024-04-02 17:42:28,650] {taskinstance.py:1377} INFO - Executing <Task(_PythonDecoratedOperator): AAPL> on 2024-01-11 00:00:00+00:00
[2024-04-02 17:42:28,659] {standard_task_runner.py:52} INFO - Started process 18651 to run task
[2024-04-02 17:42:28,687] {standard_task_runner.py:79} INFO - Running: ['airflow', 'tasks', 'run', 'get_stocks_dag', 'AAPL', 'scheduled__2024-01-11T00:00:00+00:00', '--job-id', '279', '--raw', '--subdir', 'DAGS_FOLDER/get_stocks.py', '--cfg-path', '/tmp/tmplc5bvbe0', '--error-file', '/tmp/tmpw0a6ivpe']
[2024-04-02 17:42:28,689] {standard_task_runner.py:80} INFO - Job 279: Subtask AAPL
[2024-04-02 17:42:28,841] {task_command.py:370} INFO - Running <TaskInstance: get_stocks_dag.AAPL scheduled__2024-01-11T00:00:00+00:00 [running]> on host alexmend-virtual-machine
[2024-04-02 17:42:29,048] {taskinstance.py:1569} INFO - Exporting the following env vars:
AIRFLOW_CTX_DAG_OWNER=airflow
AIRFLOW_CTX_DAG_ID=get_stocks_dag
AIRFLOW_CTX_TASK_ID=AAPL
AIRFLOW_CTX_EXECUTION_DATE=2024-01-11T00:00:00+00:00
AIRFLOW_CTX_TRY_NUMBER=1
AIRFLOW_CTX_DAG_RUN_ID=scheduled__2024-01-11T00:00:00+00:00
[2024-04-02 17:42:29,678] {python.py:173} INFO - Done. Returned value was: None
[2024-04-02 17:42:29,707] {taskinstance.py:1395} INFO - Marking task as SUCCESS. dag_id=get_stocks_dag, task_id=AAPL, execution_date=20240111T000000, start_date=20240402T204228, end_date=20240402T204229
[2024-04-02 17:42:29,733] {local_task_job.py:156} INFO - Task exited with return code 0
[2024-04-02 17:42:29,784] {local_task_job.py:273} INFO - 0 downstream tasks scheduled from follow-on schedule check
