[2024-04-02 12:56:04,651] {taskinstance.py:1159} INFO - Dependencies all met for <TaskInstance: get_stocks_dag.AAPL scheduled__2024-01-02T00:00:00+00:00 [queued]>
[2024-04-02 12:56:04,662] {taskinstance.py:1159} INFO - Dependencies all met for <TaskInstance: get_stocks_dag.AAPL scheduled__2024-01-02T00:00:00+00:00 [queued]>
[2024-04-02 12:56:04,662] {taskinstance.py:1356} INFO - 
--------------------------------------------------------------------------------
[2024-04-02 12:56:04,662] {taskinstance.py:1357} INFO - Starting attempt 1 of 1
[2024-04-02 12:56:04,662] {taskinstance.py:1358} INFO - 
--------------------------------------------------------------------------------
[2024-04-02 12:56:04,693] {taskinstance.py:1377} INFO - Executing <Task(_PythonDecoratedOperator): AAPL> on 2024-01-02 00:00:00+00:00
[2024-04-02 12:56:04,704] {standard_task_runner.py:52} INFO - Started process 7765 to run task
[2024-04-02 12:56:04,818] {standard_task_runner.py:79} INFO - Running: ['airflow', 'tasks', 'run', 'get_stocks_dag', 'AAPL', 'scheduled__2024-01-02T00:00:00+00:00', '--job-id', '7', '--raw', '--subdir', 'DAGS_FOLDER/get_stocks.py', '--cfg-path', '/tmp/tmprfvhhxtn', '--error-file', '/tmp/tmpn8zfgev4']
[2024-04-02 12:56:04,820] {standard_task_runner.py:80} INFO - Job 7: Subtask AAPL
[2024-04-02 12:56:05,317] {task_command.py:370} INFO - Running <TaskInstance: get_stocks_dag.AAPL scheduled__2024-01-02T00:00:00+00:00 [running]> on host alexmend-virtual-machine
[2024-04-02 12:56:05,416] {taskinstance.py:1569} INFO - Exporting the following env vars:
AIRFLOW_CTX_DAG_OWNER=airflow
AIRFLOW_CTX_DAG_ID=get_stocks_dag
AIRFLOW_CTX_TASK_ID=AAPL
AIRFLOW_CTX_EXECUTION_DATE=2024-01-02T00:00:00+00:00
AIRFLOW_CTX_TRY_NUMBER=1
AIRFLOW_CTX_DAG_RUN_ID=scheduled__2024-01-02T00:00:00+00:00
[2024-04-02 12:56:06,742] {history.py:222} ERROR - AAPL: No price data found, symbol may be delisted (1h 2024-01-01 -> 2024-01-02)
[2024-04-02 12:56:06,781] {python.py:173} INFO - Done. Returned value was: None
[2024-04-02 12:56:06,887] {taskinstance.py:1395} INFO - Marking task as SUCCESS. dag_id=get_stocks_dag, task_id=AAPL, execution_date=20240102T000000, start_date=20240402T155604, end_date=20240402T155606
[2024-04-02 12:56:06,953] {local_task_job.py:156} INFO - Task exited with return code 0
[2024-04-02 12:56:06,989] {local_task_job.py:273} INFO - 0 downstream tasks scheduled from follow-on schedule check
[2024-04-02 17:41:27,407] {taskinstance.py:1159} INFO - Dependencies all met for <TaskInstance: get_stocks_dag.AAPL scheduled__2024-01-02T00:00:00+00:00 [queued]>
[2024-04-02 17:41:27,421] {taskinstance.py:1159} INFO - Dependencies all met for <TaskInstance: get_stocks_dag.AAPL scheduled__2024-01-02T00:00:00+00:00 [queued]>
[2024-04-02 17:41:27,421] {taskinstance.py:1356} INFO - 
--------------------------------------------------------------------------------
[2024-04-02 17:41:27,421] {taskinstance.py:1357} INFO - Starting attempt 1 of 1
[2024-04-02 17:41:27,421] {taskinstance.py:1358} INFO - 
--------------------------------------------------------------------------------
[2024-04-02 17:41:27,444] {taskinstance.py:1377} INFO - Executing <Task(_PythonDecoratedOperator): AAPL> on 2024-01-02 00:00:00+00:00
[2024-04-02 17:41:27,451] {standard_task_runner.py:52} INFO - Started process 17705 to run task
[2024-04-02 17:41:27,460] {standard_task_runner.py:79} INFO - Running: ['airflow', 'tasks', 'run', 'get_stocks_dag', 'AAPL', 'scheduled__2024-01-02T00:00:00+00:00', '--job-id', '252', '--raw', '--subdir', 'DAGS_FOLDER/get_stocks.py', '--cfg-path', '/tmp/tmp11ozb4bc', '--error-file', '/tmp/tmpy97r25qt']
[2024-04-02 17:41:27,462] {standard_task_runner.py:80} INFO - Job 252: Subtask AAPL
[2024-04-02 17:41:28,357] {task_command.py:370} INFO - Running <TaskInstance: get_stocks_dag.AAPL scheduled__2024-01-02T00:00:00+00:00 [running]> on host alexmend-virtual-machine
[2024-04-02 17:41:29,521] {taskinstance.py:1569} INFO - Exporting the following env vars:
AIRFLOW_CTX_DAG_OWNER=airflow
AIRFLOW_CTX_DAG_ID=get_stocks_dag
AIRFLOW_CTX_TASK_ID=AAPL
AIRFLOW_CTX_EXECUTION_DATE=2024-01-02T00:00:00+00:00
AIRFLOW_CTX_TRY_NUMBER=1
AIRFLOW_CTX_DAG_RUN_ID=scheduled__2024-01-02T00:00:00+00:00
[2024-04-02 17:41:30,616] {taskinstance.py:1889} ERROR - Task failed with exception
Traceback (most recent call last):
  File "/home/alexmend/Documents/airflowalex/venv/lib/python3.9/site-packages/airflow/decorators/base.py", line 179, in execute
    return_value = super().execute(context)
  File "/home/alexmend/Documents/airflowalex/venv/lib/python3.9/site-packages/airflow/operators/python.py", line 171, in execute
    return_value = self.execute_callable()
  File "/home/alexmend/Documents/airflowalex/venv/lib/python3.9/site-packages/airflow/operators/python.py", line 189, in execute_callable
    return self.python_callable(*self.op_args, **self.op_kwargs)
  File "/home/alexmend/Documents/airflowalex/dags/get_stocks.py", line 18, in get_history
    yfinance.Ticker(ticker).history(
  File "/home/alexmend/Documents/airflowalex/venv/lib/python3.9/site-packages/yfinance/utils.py", line 103, in wrapper
    result = func(*args, **kwargs)
  File "/home/alexmend/Documents/airflowalex/venv/lib/python3.9/site-packages/yfinance/base.py", line 77, in history
    return self._lazy_load_price_history().history(*args, **kwargs)
  File "/home/alexmend/Documents/airflowalex/venv/lib/python3.9/site-packages/yfinance/utils.py", line 103, in wrapper
    result = func(*args, **kwargs)
  File "/home/alexmend/Documents/airflowalex/venv/lib/python3.9/site-packages/yfinance/scrapers/history.py", line 226, in history
    logger.debug(f'{self.ticker}: yfinance received OHLC data: {quotes.index[0]} -> {quotes.index[-1]}')
  File "/home/alexmend/Documents/airflowalex/venv/lib/python3.9/site-packages/pandas/core/indexes/base.py", line 5389, in __getitem__
    return getitem(key)
  File "/home/alexmend/Documents/airflowalex/venv/lib/python3.9/site-packages/pandas/core/arrays/datetimelike.py", line 379, in __getitem__
    result = cast("Union[Self, DTScalarOrNaT]", super().__getitem__(key))
  File "/home/alexmend/Documents/airflowalex/venv/lib/python3.9/site-packages/pandas/core/arrays/_mixins.py", line 284, in __getitem__
    result = self._ndarray[key]
IndexError: index 0 is out of bounds for axis 0 with size 0
[2024-04-02 17:41:30,692] {taskinstance.py:1395} INFO - Marking task as FAILED. dag_id=get_stocks_dag, task_id=AAPL, execution_date=20240102T000000, start_date=20240402T204127, end_date=20240402T204130
[2024-04-02 17:41:30,771] {standard_task_runner.py:92} ERROR - Failed to execute job 252 for task AAPL (index 0 is out of bounds for axis 0 with size 0; 17705)
[2024-04-02 17:41:30,845] {local_task_job.py:156} INFO - Task exited with return code 1
[2024-04-02 17:41:30,954] {local_task_job.py:273} INFO - 0 downstream tasks scheduled from follow-on schedule check
